<?xml version="1.0"?>
<robot name="unicycle_ugv" xmlns:xacro="http://ros.org/wiki/xacro">

  <xacro:arg name="robot_name" default="ugv"/>
  
  <xacro:property name="chassis_length" value="0.3"/>
  <xacro:property name="chassis_width" value="0.2"/>
  <xacro:property name="chassis_height" value="0.1"/>
  <xacro:property name="wheel_radius" value="0.05"/>
  <xacro:property name="wheel_width" value="0.02"/>

  <xacro:macro name="box_inertia" params="m w h d">
    <inertial>
      <mass value="${m}"/>
      <inertia ixx="${(m/12) * (h*h + d*d)}" ixy="0.0" ixz="0.0" 
               iyy="${(m/12) * (w*w + d*d)}" iyz="0.0" 
               izz="${(m/12) * (w*w + h*h)}"/>
    </inertial>
  </xacro:macro>

  <xacro:macro name="cylinder_inertia" params="m r h">
    <inertial>
      <mass value="${m}"/>
      <inertia ixx="${(m/12) * (3*r*r + h*h)}" ixy="0" ixz="0" 
               iyy="${(m/12) * (3*r*r + h*h)}" iyz="0" 
               izz="${(m/2) * (r*r)}"/>
    </inertial>
  </xacro:macro>


  <link name="$(arg robot_name)/base_link">
    <visual>
      <geometry>
        <box size="${chassis_length} ${chassis_width} ${chassis_height}"/>
      </geometry>
      <material name="blue">
        <color rgba="0 0 0.8 1"/>
      </material>
    </visual>
    <collision>
      <geometry>
        <box size="${chassis_length} ${chassis_width} ${chassis_height}"/>
      </geometry>
    </collision>
    <xacro:box_inertia m="1.0" w="${chassis_width}" h="${chassis_height}" d="${chassis_length}"/>
  </link>

  <link name="$(arg robot_name)/left_wheel">
    <visual>
      <geometry>
        <cylinder radius="${wheel_radius}" length="${wheel_width}"/>
      </geometry>
      <material name="black">
        <color rgba="0 0 0 1"/>
      </material>
    </visual>
    <collision>
      <geometry>
        <cylinder radius="${wheel_radius}" length="${wheel_width}"/>
      </geometry>
    </collision>
    <xacro:cylinder_inertia m="0.2" r="${wheel_radius}" h="${wheel_width}"/>
  </link>

  <joint name="left_wheel_joint" type="continuous">
    <parent link="$(arg robot_name)/base_link"/>
    <child link="$(arg robot_name)/left_wheel"/>
    <origin xyz="0.05 ${chassis_width/2 + wheel_width/2} -0.05" rpy="-1.5708 0 0"/>
    <axis xyz="0 0 1"/>
  </joint>

  <link name="$(arg robot_name)/right_wheel">
    <visual>
      <geometry>
        <cylinder radius="${wheel_radius}" length="${wheel_width}"/>
      </geometry>
      <material name="black"/>
    </visual>
    <collision>
      <geometry>
        <cylinder radius="${wheel_radius}" length="${wheel_width}"/>
      </geometry>
    </collision>
    <xacro:cylinder_inertia m="0.2" r="${wheel_radius}" h="${wheel_width}"/>
  </link>

  <joint name="right_wheel_joint" type="continuous">
    <parent link="$(arg robot_name)/base_link"/>
    <child link="$(arg robot_name)/right_wheel"/>
    <origin xyz="0.05 -${chassis_width/2 + wheel_width/2} -0.05" rpy="-1.5708 0 0"/>
    <axis xyz="0 0 1"/>
  </joint>

  <link name="$(arg robot_name)/caster_wheel">
    <visual>
      <geometry>
        <sphere radius="${wheel_radius / 2}"/>
      </geometry>
      <material name="black"/>
    </visual>
    <collision>
      <geometry>
        <sphere radius="${wheel_radius / 2}"/>
      </geometry>
    </collision>
    <inertial>
      <mass value="0.1"/>
      <inertia ixx="0.0001" ixy="0.0" ixz="0.0" iyy="0.0001" iyz="0.0" izz="0.0001"/>
    </inertial>
  </link>

  <joint name="caster_joint" type="fixed">
    <parent link="$(arg robot_name)/base_link"/>
    <child link="$(arg robot_name)/caster_wheel"/>
    <origin xyz="-0.1 0 -0.075" rpy="0 0 0"/>
  </joint>

  <gazebo reference="$(arg robot_name)/caster_wheel">
    <mu1>0.0</mu1>
    <mu2>0.0</mu2>
  </gazebo>


  <gazebo>
    <plugin name="diff_drive_controller" filename="libgazebo_ros_diff_drive.so">
      
      <ros>
        <namespace>/$(arg robot_name)</namespace>
      </ros>

      <left_joint>left_wheel_joint</left_joint>
      <right_joint>right_wheel_joint</right_joint>
      <wheel_separation>${chassis_width + wheel_width}</wheel_separation>
      <wheel_diameter>${wheel_radius * 2}</wheel_diameter>

      <publish_odom>true</publish_odom>
      <publish_odom_tf>true</publish_odom_tf>
      <publish_wheel_tf>true</publish_wheel_tf>

      <odometry_frame>$(arg robot_name)/odom</odometry_frame>
      <robot_base_frame>$(arg robot_name)/base_link</robot_base_frame>

    </plugin>
  </gazebo>

</robot>